Workbook

Sheet kosztorys
B2: Kosztorys prac budowlanych/ remontowych/ wykończeniowych | J2: wer. 03
B3: Inwestor/Kredytobiorca: | I3: Rodzaj nieruchomości:
B4: Powierzchnia użytkowa [m2] | G4: Rodzaj inwestycji:
B5: Kod pocztowy: | F5: Województwo: | G5: mazowieckie | H5: Miejscowość | ulica, nr budynku lub nr działki nr lokalu (jeżeli dotyczy)
B6: Podpiwniczenie | G6: Powierzchnia zabudowy [m2] | I6: Powierzchnia całkowita
B7: Docelowy standard wykończenia | G7: =IF(EXACT($J$3,"Lokal mieszkalny"),IF(ISBLANK(E1),"Czy Twoje mieszkanie jest piętrowe? Podaj liczbę kondygnacji (poddasze ze skosami jako 0,5):","Na ilu kondygnacjach położone jest Twoje mieszkanie (poddasze jako 0,5):"),"Liczba kondygnacji nadziemnych (poddasze jako 0,5):") -> Liczba kondygnacji nadziemnych (poddasze jako 0,5): | I7: Rodzaj zabudowy:
B9: =IF(EXACT(E1,"Załącznik do Umowy"),"",IF(AND(NOT(EXACT($J$3,"Lokal mieszkalny")),EXACT($H$4,"Budowa"),$F$4>0,NOT(ISBLANK($F$6)),NOT(ISBLANK($J$7))),CONCATENATE("Przeciętny koszt wybudowania domu wynosi"," ",ROUND(Wyliczenia!Q7,-3)," zł"),IF(AND(EXACT($J$3,"Lokal mieszkalny"),EXACT($H$4,"Prace wykończeniowe"),NOT(EXACT($F$7,"Deweloperski")),$F$4>0,NOT(ISBLANK($G$5)),NOT(ISBLANK($F$7))),CONCATENATE("Przeciętny koszt prac wykończeniowych lokalu mieszkalnego wynosi"," ",_xlfn.IFNA(HLOOKUP(F7,Wyliczenia!R1:U7,7,FALSE),Wyliczenia!S7)," zł"),"")))
B10: Wnioskowany kredyt na pokrycie kosztów budowy / remontu / wykończenia[zł]
B11: 1 kolumna | G11: 5 kolumna | H11: 2 kolumna | I11: 3 kolumna | J11: 6 kolumna | K11: 4 kolumna | L11: Przed dewelopmentem potwierdźmy układ na stronie
B12: Elementy robót budowlanych | G12: Opis, uwagi (wyjaśniające koszty): np. materiał i liczba dla materiałów[m2, sztuki] | H12: Całkowity koszt elementu | I12: Aktualne zaawansowanie | J12: Opis wydatkowania środków (jeśli inny niż wykonanie prac) | K12: Aktualne zaawansowanie wg firmy zewnętrznej Różnica w stosunku do przeciętnych kosztów
H13: (zł) | I13: [%]
B14: + | C14: Przyłącza | G14: =IF(EXACT(E1,"Załącznik do Umowy"),"",IF(AND(NOT(EXACT($J$3,"Lokal mieszkalny")),EXACT(LEFT($H$4,6),"Budowa"),$F$4>0,NOT(ISBLANK($F$6)),NOT(ISBLANK($J$7)),Wyliczenia!AC24>0),CONCATENATE("Przeciętne koszty wykonania przyłączy wynoszą"," ",Wyliczenia!R24,"zł"),"")) | H14: =IF(Wyliczenia!AC24>0,Wyliczenia!AG24,"") | I14: =IF(Wyliczenia!AE24>0,Wyliczenia!AH24,"") | J14: =IF(Wyliczenia!AC24>0,Wyliczenia!AF24,"") | K14: =IF(AND(NOT(EXACT($J$3,"Lokal mieszkalny")),EXACT(LEFT($H$4,6),"Budowa"),$F$4>0,NOT(ISBLANK($F$6)),NOT(ISBLANK($J$7)),Wyliczenia!AC24>0),Wyliczenia!AJ24,"")
C15: Przyłącze wodne | K15: 0.1
C16: Przyłącze kanalizacyjne | K16: 0.5
C17: Przyłącze gazowe
C18: Przyłącze energetyczne
C19: Przyłącze inne, jakie ?
B20: + | C20: Stan zerowy | G20: =IF(EXACT(E1,"Załącznik do Umowy"),"",IF(AND(NOT(EXACT($J$3,"Lokal mieszkalny")),EXACT(LEFT($H$4,6),"Budowa"),$F$4>0,NOT(ISBLANK($F$6)),NOT(ISBLANK($J$7)),Wyliczenia!AC30>0),CONCATENATE("Przeciętne koszty wykonania stanu zerowego wynoszą"," ",Wyliczenia!R30,"zł"),"")) | H20: =IF(Wyliczenia!AC30>0,Wyliczenia!AG30,"") | I20: =IF(Wyliczenia!AE30>0,Wyliczenia!AH30,"") | J20: =IF(Wyliczenia!AC30>0,Wyliczenia!AF30,"") | K20: =IF(AND(NOT(EXACT($J$3,"Lokal mieszkalny")),EXACT(LEFT($H$4,6),"Budowa"),$F$4>0,NOT(ISBLANK($F$6)),NOT(ISBLANK($J$7)),Wyliczenia!AC30>0),Wyliczenia!AJ30,"")
C21: Roboty ziemne | K21: 0.1
C22: Fundamenty, ściany fundamentowe, izolacje , płyta fundamentowa
C23: Ściany podziemia (podpiwniczenie)
C24: Strop na poziomie zero, schody podziemia (podpiwniczenie)
C25: Inne……
B26: + | C26: Stan surowy | G26: =IF(EXACT(E1,"Załącznik do Umowy"),"",IF(AND(NOT(EXACT($J$3,"Lokal mieszkalny")),EXACT($H$4,"Budowa"),$F$4>0,NOT(ISBLANK($F$6)),NOT(ISBLANK($J$7)),Wyliczenia!AC36>0),CONCATENATE("Przeciętne koszty wykonania stanu surowego wynoszą"," ",Wyliczenia!R36,"zł"),"")) | H26: =IF(Wyliczenia!AC36>0,Wyliczenia!AG36,"") | I26: =IF(Wyliczenia!AE36>0,Wyliczenia!AH36,"") | J26: =IF(Wyliczenia!AC36>0,Wyliczenia!AF36,"") | K26: =IF(AND(NOT(EXACT($J$3,"Lokal mieszkalny")),EXACT(LEFT($H$4,6),"Budowa"),$F$4>0,NOT(ISBLANK($F$6)),NOT(ISBLANK($J$7)),Wyliczenia!AC36>0),Wyliczenia!AJ36,"")
C27: Ściany konstrukcyjne zewnętrzne, kominy dymowe i wentylacyjne
C28: Ściany działowe | K28: 0.79
C29: Stropy (w tym tarasy, balkony)
C30: Konstrukcja i pokrycie dachu
C31: Inne……
B32: + | C32: Stan deweloperski | G32: =IF(EXACT(E1,"Załącznik do Umowy"),"",IF(AND(NOT(EXACT($J$3,"Lokal mieszkalny")),EXACT(LEFT($H$4,6),"Budowa"),$F$4>0,NOT(ISBLANK($F$6)),NOT(ISBLANK($J$7)),Wyliczenia!AC42>0),CONCATENATE("Przeciętne koszty wykonania stanu deweloperskiego"," ",Wyliczenia!R42,"zł"),"")) | H32: =IF(Wyliczenia!AC42>0,Wyliczenia!AG42,"") | I32: =IF(Wyliczenia!AE42>0,Wyliczenia!AH42,"") | J32: =IF(Wyliczenia!AC42>0,Wyliczenia!AF42,"") | K32: =IF(AND(NOT(EXACT($J$3,"Lokal mieszkalny")),EXACT(LEFT($H$4,6),"Budowa"),$F$4>0,NOT(ISBLANK($F$6)),NOT(ISBLANK($J$7)),Wyliczenia!AC42>0),Wyliczenia!AJ42,"")
C33: Schody (konstrukcja + wykończenie)
C34: Tynki wewnętrzne (wszystkie pomieszczenia)
C35: Stolarka okienna, drzwiowa zewnętrzna
C36: Podłoża, wylewki (wszystkie pomieszczenia)
C37: Elementy ślusarsko-kowalskie (poręcze, balustrady)
C38: Elewacja - ocieplenie, tynk zewnętrzny
C39: Ocieplenie dachu
C40: Inne……
B41: + | C41: Instalacje | G41: =IF(EXACT(E1,"Załącznik do Umowy"),"",IF(AND(NOT(EXACT($J$3,"Lokal mieszkalny")),EXACT(LEFT($H$4,6),"Budowa"),$F$4>0,NOT(ISBLANK($F$6)),NOT(ISBLANK($J$7)),Wyliczenia!AC51>0),CONCATENATE("Przeciętne koszty wykonania instalacji wynoszą"," ",Wyliczenia!R51,"zł"),"")) | H41: =IF(Wyliczenia!AC51>0,Wyliczenia!AG51,"") | I41: =IF(Wyliczenia!AE51>0,Wyliczenia!AH51,"") | J41: =IF(Wyliczenia!AC51>0,Wyliczenia!AF51,"") | K41: =IF(AND(NOT(EXACT($J$3,"Lokal mieszkalny")),EXACT(LEFT($H$4,6),"Budowa"),$F$4>0,NOT(ISBLANK($F$6)),NOT(ISBLANK($J$7)),Wyliczenia!AC51>0),Wyliczenia!AJ51,"")
C42: Instalacja wodna, kanalizacyjna (biały montaż jeśli brak wykończenia "pod klucz")
...

Sheet Zasady wypełniania formularza
B1: Zasady wypełniania formularza
B3: Formularz wykorzystasz do określenia prac na etapie składania wniosku kredytowego
B4: Pole formularza oznaczyliśmy kolorem | F4: białym | H4: wymaga uzupełnienia
F5: szarym | H5: nie wymaga uzupełnienia
F6: czerwonym | H6: wartość do korekty, błąd w wypełnieniu
B8: Wydruk kosztorysu: | D8: Jeśli wydrukujesz kosztorys na 2 lub więcej stronach musisz zaparafować każdą stronę
D9: i podpisać kosztorys na ostatniej stronie (wymagamy podpisów wszystkich wnioskodawców)
B11: W kosztorysie wprowadzasz prace budowlane i koszty poniesione przez Ciebie od od momentu nabycia nieruchomości
B70: *Jeżeli wnioskodawca jest jedynym właścicielem działki i nabył ze środków własnych, albo kredyt na działkę został już spłacony, to wartość działki pomniejsza wymagany wkład własny na budowę

Sheet Wyliczenia
A1: NOWY | B1: STARY | D1: Deweloperski | E1: Średni | F1: Podwyższony | G1: Wysoki | H1: piwnica | J1: wolnostojąca | K1: 0 | L1: 1 | M1: Deweloperski | N1: =D2 -> 0 | O1: =E59 -> 0.06 | P1: =$R$3*O1 -> 0 | Q1: =N1+IF($AC$24>$R$24,$R$24,$AC$24)+IF($AC$67>$R$67,$R$67,$AC$67) -> #N/A | R1: Deweloperski | S1: Średni | T1: Podwyższony | U1: Wysoki | V1: plus na kuchnię i łazienkę | AB1: Stawka podstawowa | AD1: Współczynnik regionalny
D2: =kosztorys!$F$4*Wyliczenia!$D$3 -> 0 | E2: =kosztorys!$F$4*Wyliczenia!E3+$V$2 -> 31134.6 | F2: =kosztorys!$F$4*Wyliczenia!F3+$V$2 -> 31134.6 | G2: =kosztorys!$F$4*Wyliczenia!G3+$V$2 -> 31134.6 | H2: NIE | I2: 0 | J2: bliźniacza | K2: =$R$2*S15 -> -324.319 | L2: 0.75 | M2: Średni | N2: =E2 -> 31134.6 | O2: =$S$4 -> 0.24 | P2: =$R$3*O2+$V$2 -> 31134.6 | Q2: =N2+IF($AC$24>$R$24,$R$24,$AC$24)+IF($AC$67>$R$67,$R$67,$AC$67) -> #N/A | R2: =ROUND(IF(kosztorys!$F$4=120,$AB$4,$AB$4*IF((1+(1-(kosztorys!$F$4/120))/3)>T21,T21,IF((1+(1-(kosztorys!$F$4/120))/3)<T20,T20,(1+(1-(kosztorys!$F$4/120))/3)))),2) -> 6486.38 | S2: =$R$2*S4 -> 1556.7312 | T2: =$R$2*T4 -> 843.2294 | U2: =$R$2*U4 -> 972.957 | V2: =$AB$4*V4 -> 31134.6 | AB2: 4900 | AC2: dolnośląskie | AD2: 1.014
D3: =IFERROR($R$2+VLOOKUP(kosztorys!$F$6,Wyliczenia!$H$2:$I$3,2,TRUE)+VLOOKUP(kosztorys!$J$7,Wyliczenia!$J$1:$K$4,2,FALSE)+IF(kosztorys!$H$7>=2,Wyliczenia!$I$5,0),0) -> 0 | E3: =D3+S2 -> 1556.7312 | F3: =E3+T2 -> 2399.9606 | G3: =F3+U2 -> 3372.9176 | H3: TAK | I3: =$R$2*S13 -> 389.1828 | J3: szeregowa | K3: =$R$2*S16 -> -518.9104 | L3: 0.45 | M3: Podwyższony | N3: =F2 -> 31134.6 | O3: =$S$4+$T$4 -> 0.37 | P3: =$R$3*O3+$V$2 -> 31134.6 | Q3: =N3+IF($AC$24>$R$24,$R$24,$AC$24)+IF($AC$67>$R$67,$R$67,$AC$67) -> #N/A | R3: =R2*kosztorys!F4 -> 0 | AB3: Stawka regionalna | AC3: kujawsko-pomorskie | AD3: 0.972
J4: wielorodzinny | K4: 0 | L4: 0.25 | M4: Wysoki | N4: =G2 -> 31134.6 | O4: =$O$3+$U$4 -> 0.52 | P4: =$R$3*O4+$V$2 -> 31134.6 | Q4: =N4+IF($AC$24>$R$24,$R$24,$AC$24)+IF($AC$67>$R$67,$R$67,$AC$67) -> #N/A | R4: BMJ Parametr standard | S4: 0.24 | T4: 0.13 | U4: 0.15 | V4: 6 | AB4: =AB2*_xlfn.IFNA(IF(AND(EXACT(UPPER(kosztorys!I5),"WARSZAWA"),EXACT(kosztorys!G5,"mazowieckie")),Wyliczenia!AD18,VLOOKUP(kosztorys!G5,Wyliczenia!AC2:AD18,2,FALSE)),1) -> 5189.1 | AC4: lubelskie | AD4: 0.94
H5: kondygnacje | I5: =$R$2*$S$14 -> 454.0466 | M5: Inny | N5: =E2 -> 31134.6 | O5: =O3 -> 0.37 | P5: =$R$3*O5+$V$2 -> 31134.6 | Q5: =N5+IF($AC$24>$R$24,$R$24,$AC$24)+IF($AC$67>$R$67,$R$67,$AC$67) -> #N/A | R5: LM Parametr standard | S5: 0.22 | T5: 0.13 | U5: 0.15 | V5: 5 | AC5: lubuskie | AD5: 0.963
Q6: Cała budowa | R6: LM wykończenie m2 | S6: =$R$2*S5 -> 1427.0036 | T6: =$R$2*T5 -> 843.2294 | U6: =$R$2*U5 -> 972.957 | V6: =$R$2*V5 -> 32431.9 | AC6: łódzkie | AD6: 0.96
Q7: =R82 -> #N/A | R7: 0 | S7: =ROUND(kosztorys!$F$4*Wyliczenia!S6+Wyliczenia!$V$6,-3) -> 32000 | T7: =ROUND(kosztorys!$F$4*Wyliczenia!T6+Wyliczenia!S7,-3) -> 32000 | U7: =ROUND(kosztorys!$F$4*Wyliczenia!U6+Wyliczenia!T7,-3) -> 32000 | V7: zł | AC7: małopolskie | AD7: 1.015
N8: =$N$1+S59 -> 0 | O8: =$N$1+T59 -> 0 | P8: =$N$1+U59 -> 0 | R8: LM wykończenie całość | S8: =S7/kosztorys!$F$4 -> #DIV/0! | T8: =T7/kosztorys!$F$4 -> #DIV/0! | U8: =U7/kosztorys!$F$4 -> #DIV/0! | V8: zł/m2 | AC8: mazowieckie | AD8: 1.059
N9: =N1+P2 -> 31134.6 | AC9: opolskie | AD9: 1.011
R10: Akceptowane różnice sygnały | S10: 0.15 | T10: zielony | AC10: podkarpackie | AD10: 0.993
R11: parametry | S11: -0.15 | T11: czerwony | AC11: podlaskie | AD11: 0.968
AC12: pomorskie | AD12: 1.011
R13: Piwnica | S13: 0.06 | AC13: śląskie | AD13: 1.022
N14: Tym kolorem zaznaczyłem paramerty do tabeli parametrów | R14: Kondygnacje więcej niż 2 | S14: 0.07 | AC14: świętokrzyskie | AD14: 0.961
R15: Zabudowa bliżniacza | S15: -0.05 | AC15: warmińsko-mazurskie | AD15: 0.957
R16: Zabudowa szeregowa | S16: -0.08 | AC16: wielkopolskie | AD16: 1.046
AB17: Część dla specjalisty w BANKU | AC17: zachodniopomorskie | AD17: 1.056
R18: Dom pasywny | S18: 0.2 | T18: parametr do dodania w przyszłości | AC18: Warszawa | AD18: 1.126
R20: Parametr zmiany ze względu na powierzchnię | T20: 0.8
R21: Parametr zmiany ze względu na powierzchnię | T21: 1.25
C22: "Formaty warunkowe = F" | AB22: % zaawansowania prac wykonanych
C23: Ekrany | D23: dewelop | E23: Parametr % | R23: Średnie koszty | AC23: Koszt elementu | AF23: pozostało | AG23: % sekcja | AH23: % wykonania ogółem
A24: PRZYŁĄCZA | B24: Paramert który nie jest doliczny do ceny m2 i wykracza ponad 100% | C24: =F24 -> FALSE | D24: =E24 -> 0.08 | E24: 0.08 | F24: =IF(AC24>0,TRUE,IF(OR(EXACT(LEFT(kosztorys!$H$4,6),"Budowa"),EXACT(kosztorys!$H$4,"Przebudowa/Rozbudowa/Nadbudowa")),TRUE,FALSE)) -> FALSE | R24: =ROUND($AB$4*120*D24,-3) -> 50000 | AA24: =IFERROR(AC24/kosztorys!$H$71,) -> 0 | AB24: =IFERROR(AE24/kosztorys!$H$71,) -> 0 | AC24: =SUM(kosztorys!H15:H19) -> 0 | AE24: =SUM(AE25:AE29) -> 0 | AF24: =CONCATENATE("Do wykonania prace za ",ROUND(AC24-AE24,2),"zł") -> Do wykonania prace za 0zł | AG24: =CONCATENATE($AC24,"zł to ",ROUND(AA24*100,2),"%") -> 0zł to 0% | AH24: =CONCATENATE($AE24,"zł to ",ROUND(AB24*100,2),"%") -> 0zł to 0% | AI24: =kosztorys!H14 | AJ24: =ROUND(IFERROR(((Wyliczenia!AC24-IF(AC24>R24,R24,AC24))/IF(AC24>R24,R24,AC24)),""),3) -> #VALUE! | AK24: =kosztorys!K14
A25: Przyłącze wodne | AE25: =kosztorys!H15*kosztorys!I15 -> 0 | AI25: =kosztorys!H15 -> 0 | AJ25: =kosztorys!I15 -> 0 | AK25: =kosztorys!K15 -> 0.1
A26: Przyłącze kanalizacyjne | AE26: =kosztorys!H16*kosztorys!I16 -> 0 | AI26: =kosztorys!H16 -> 0 | AJ26: =kosztorys!I16 -> 0 | AK26: =kosztorys!K16 -> 0.5
A27: Przyłącze gazowe | AE27: =kosztorys!H17*kosztorys!I17 -> 0 | AI27: =kosztorys!H17 -> 0 | AJ27: =kosztorys!I17 -> 0 | AK27: =kosztorys!K17 -> 0
A28: Przyłącze energetyczne | AE28: =kosztorys!H18*kosztorys!I18 -> 0 | AI28: =kosztorys!H18 -> 0 | AJ28: =kosztorys!I18 -> 0 | AK28: =kosztorys!K18 -> 0
A29: Przyłącze inne, jakie ? | AE29: =kosztorys!H19*kosztorys!I19 -> 0 | AI29: =kosztorys!H19 -> 0 | AJ29: =kosztorys!I19 -> 0 | AK29: =kosztorys!K19 -> 0
A30: STAN ZEROWY | B30: Parametr dla standardu Deweloperskiego | C30: =F30 -> FALSE | D30: =IF(EXACT(kosztorys!$F$6,"NIE"),E30,E30+4%) -> 0.16 | E30: 0.12 | F30: =IF(AC30>0,TRUE,IF(EXACT(kosztorys!$H$4,"Budowa"),TRUE,FALSE)) -> FALSE | R30: =ROUND($D$2*D30,-3) -> 0 | AA30: =IFERROR(AC30/kosztorys!$H$71,) -> 0 | AB30: =IFERROR(AE30/kosztorys!$H$71,) -> 0 | AC30: =SUM(kosztorys!H21:H25) -> 0 | AE30: =SUM(AE31:AE35) -> 0 | AF30: =CONCATENATE("Do wykonania prace za ",ROUND(AC30-AE30,2),"zł") -> Do wykonania prace za 0zł | AG30: =CONCATENATE($AC30,"zł to ",ROUND(AA30*100,2),"%") -> 0zł to 0% | AH30: =CONCATENATE($AE30,"zł to ",ROUND(AB30*100,2),"%") -> 0zł to 0% | AI30: =kosztorys!H20 | AJ30: =IFERROR(ROUND(((Wyliczenia!AC30-Wyliczenia!R30)/Wyliczenia!R30),3),"") | AK30: =kosztorys!K20
A31: Roboty ziemne | AE31: =kosztorys!H21*kosztorys!I21 -> 0 | AI31: =kosztorys!H21 -> 0 | AJ31: =kosztorys!I21 -> 0 | AK31: =kosztorys!K21 -> 0.1
A32: Fundamenty, ściany fundamentowe, izolacje , płyta fundamentowa | AE32: =kosztorys!H22*kosztorys!I22 -> 0 | AI32: =kosztorys!H22 -> 0 | AJ32: =kosztorys!I22 -> 0 | AK32: =kosztorys!K22 -> 0
A33: Ściany podziemia (podpiwniczenie) | AE33: =kosztorys!H23*kosztorys!I23 -> 0 | AI33: =kosztorys!H23 -> 0 | AJ33: =kosztorys!I23 -> 0 | AK33: =kosztorys!K23 -> 0
A34: Strop na poziomie zero, schody podziemia (podpiwniczenie) | AE34: =kosztorys!H24*kosztorys!I24 -> 0 | AI34: =kosztorys!H24 -> 0 | AJ34: =kosztorys!I24 -> 0 | AK34: =kosztorys!K24 -> 0
A35: Inne…… | AE35: =kosztorys!H25*kosztorys!I25 -> 0 | AI35: =kosztorys!H25 -> 0 | AJ35: =kosztorys!I25 -> 0 | AK35: =kosztorys!K25 -> 0
A36: STAN SUROWY | B36: Parametr dla standardu Deweloperskiego | C36: =OR(C30,F36) -> FALSE | D36: =IF(EXACT(kosztorys!$F$6,"NIE"),E36,E36-2%) -> 0.3 | E36: 0.32 | F36: =IF(AC36>0,TRUE,IF(EXACT(kosztorys!$H$4,"Budowa"),TRUE,FALSE)) -> FALSE | R36: =ROUND($D$2*D36,-3) -> 0 | AA36: =IFERROR(AC36/kosztorys!$H$71,) -> 0 | AB36: =IFERROR(AE36/kosztorys!$H$71,) -> 0 | AC36: =SUM(kosztorys!H27:H31) -> 0 | AE36: =SUM(AE37:AE41) -> 0 | AF36: =CONCATENATE("Do wykonania prace za ",ROUND(AC36-AE36,2),"zł") -> Do wykonania prace za 0zł | AG36: =CONCATENATE($AC36,"zł to ",ROUND(AA36*100,2),"%") -> 0zł to 0% | AH36: =CONCATENATE($AE36,"zł to ",ROUND(AB36*100,2),"%") -> 0zł to 0% | AI36: =kosztorys!H26 | AJ36: =IFERROR(ROUND(((Wyliczenia!AC36-Wyliczenia!R36)/Wyliczenia!R36),3),"") | AK36: =kosztorys!K26
A37: Ściany konstrukcyjne zewnętrzne, kominy dymowe i wentylacyjne | AE37: =kosztorys!H27*kosztorys!I27 -> 0 | AI37: =kosztorys!H27 -> 0 | AJ37: =kosztorys!I27 -> 0 | AK37: =kosztorys!K27 -> 0
A38: Ściany działowe | AE38: =kosztorys!H28*kosztorys!I28 -> 0 | AI38: =kosztorys!H28 -> 0 | AJ38: =kosztorys!I28 -> 0 | AK38: =kosztorys!K28 -> 0.79
A39: Stropy (w tym tarasy, balkony) | AE39: =kosztorys!H29*kosztorys!I29 -> 0 | AI39: =kosztorys!H29 -> 0 | AJ39: =kosztorys!I29 -> 0 | AK39: =kosztorys!K29 -> 0
A40: Konstrukcja i pokrycie dachu | AE40: =kosztorys!H30*kosztorys!I30 -> 0 | AI40: =kosztorys!H30 -> 0 | AJ40: =kosztorys!I30 -> 0 | AK40: =kosztorys!K30 -> 0
A41: Inne…… | AE41: =kosztorys!H31*kosztorys!I31 -> 0 | AI41: =kosztorys!H31 -> 0 | AJ41: =kosztorys!I31 -> 0 | AK41: =kosztorys!K31 -> 0
...
